/*
 * Copyright (C) 2019 Ondrej Starek
 *
 * This file is part of OTest2.
 *
 * OTest2 is free software: you can redistribute it and/or modify it under
 * the terms of the GNU Lesser General Public License as published by
 * the Free Software Foundation, either version 3 of the License,
 * or (at your option) any later version.
 *
 * OTest2 is distributed in the hope that it will be useful, but WITHOUT
 * ANY WARRANTY; without even the implied warranty of MERCHANTABILITY
 * or FITNESS FOR A PARTICULAR PURPOSE.  See the GNU Lesser General Public
 * License for more details.
 *
 * You should have received a copy of the GNU Lesser General Public License
 * along with OTest2.  If not, see <http://www.gnu.org/licenses/>.
 */

#include <otest2/otest2.h>

#include <iostream>
#include <vector>

#include "runtime.h"

namespace OTest2 {

namespace Test {

TEST_SUITE(ExceptionsSuite) {
  TEST_CASE(MarkedTryCatch) {
    Runtime runtime("ExceptionsSuite", "MarkedTryCatch");

    TEST_SIMPLE() {
      std::vector<const char*> data_{
        "enterTest<selftest>",
        "enterSuite<ExceptionsSuite>",
        "enterCase<MarkedTryCatch>",
        "enterState<AnonymousState>",
        "assert<check 'a == b' has passed>: passed",
        "message<a = 'std::bad_exception'>",
        "message<b = 'std::bad_exception'>",
        "leaveAssert<>",
        "assert<the expected exception is caught>: passed",
        "leaveAssert<>",
        "assert<an exception is expected but no one has occurred>: failed",
        "leaveAssert<>",
        "assert<unexpected exception: foo>: failed",
        "leaveAssert<>",
        "leaveState<AnonymousState>: failed",
        "leaveCase<MarkedTryCatch>: failed",
        "leaveSuite<ExceptionsSuite>: failed",
        "leaveTest<selftest>: failed",
      };

      testAssert(!runtime.runTheTest());
      testAssert(runtime.reporter.checkRecords(data_));
//      runtime.reporter.dumpRecords(std::cout);
    }
  }

  TEST_CASE(UnhandledException) {
    Runtime runtime("ExceptionsSuite", "UnhandledException");

    TEST_SIMPLE() {
      std::vector<const char*> data_{
        "enterTest<selftest>",
        "enterSuite<ExceptionsSuite>",
        "enterCase<UnhandledException>",
        "enterState<AnonymousState>",
        "error<unexpected exception: std::bad_exception>: failed",
        "leaveAssert<>",
        "leaveState<AnonymousState>: failed",
        "leaveCase<UnhandledException>: failed",
        "leaveSuite<ExceptionsSuite>: failed",
        "leaveTest<selftest>: failed",
      };

      testAssert(!runtime.runTheTest());
      testAssert(runtime.reporter.checkRecords(data_));
//      runtime.reporter.dumpRecords(std::cout);
    }
  }

  TEST_CASE(ExceptionFromCaseStartUp) {
    Runtime runtime("ExceptionsSuite", "ExceptionFromCaseStartUp", Runtime::report_paths_mark);

    TEST_SIMPLE() {
      std::vector<const char*> data_{
        "enterTest<selftest>",
        "path: selftest",
        "enterSuite<ExceptionsSuite>",
        "path: selftest::ExceptionsSuite",
        "enterCase<ExceptionFromCaseStartUp>",
        "path: selftest::ExceptionsSuite::ExceptionFromCaseStartUp",
        "error<unexpected exception: std::bad_exception>: failed",
        "path: selftest::ExceptionsSuite::ExceptionFromCaseStartUp",
        "leaveAssert<>",
        "path: selftest::ExceptionsSuite::ExceptionFromCaseStartUp",
        "leaveCase<ExceptionFromCaseStartUp>: failed",
        "path: selftest::ExceptionsSuite::ExceptionFromCaseStartUp",
        "leaveSuite<ExceptionsSuite>: failed",
        "path: selftest::ExceptionsSuite",
        "leaveTest<selftest>: failed",
        "path: selftest",
      };

      testAssert(!runtime.runTheTest());
      testAssert(runtime.reporter.checkRecords(data_));
//      runtime.reporter.dumpRecords(std::cout);
    }
  }

  TEST_CASE(ExceptionFromCaseTearDown) {
    Runtime runtime("ExceptionsSuite", "ExceptionFromCaseTearDown", Runtime::report_paths_mark);

    TEST_SIMPLE() {
      std::vector<const char*> data_{
        "enterTest<selftest>",
        "path: selftest",
        "enterSuite<ExceptionsSuite>",
        "path: selftest::ExceptionsSuite",
        "enterCase<ExceptionFromCaseTearDown>",
        "path: selftest::ExceptionsSuite::ExceptionFromCaseTearDown",
        "enterState<AnonymousState>",
        "path: selftest::ExceptionsSuite::ExceptionFromCaseTearDown",
        "leaveState<AnonymousState>: passed",
        "path: selftest::ExceptionsSuite::ExceptionFromCaseTearDown",
        "error<unexpected exception: std::bad_exception>: failed",
        "path: selftest::ExceptionsSuite::ExceptionFromCaseTearDown",
        "leaveAssert<>",
        "path: selftest::ExceptionsSuite::ExceptionFromCaseTearDown",
        "leaveCase<ExceptionFromCaseTearDown>: failed",
        "path: selftest::ExceptionsSuite::ExceptionFromCaseTearDown",
        "leaveSuite<ExceptionsSuite>: failed",
        "path: selftest::ExceptionsSuite",
        "leaveTest<selftest>: failed",
        "path: selftest",
      };

      testAssert(!runtime.runTheTest());
      testAssert(runtime.reporter.checkRecords(data_));
//      runtime.reporter.dumpRecords(std::cout);
    }
  }

  TEST_CASE(ExceptionFromSuiteStartUp) {
    Runtime runtime("ExceptionFromSuiteStartUp", "", Runtime::report_paths_mark);

    TEST_SIMPLE() {
      std::vector<const char*> data_{
        "enterTest<selftest>",
        "path: selftest",
        "enterSuite<ExceptionFromSuiteStartUp>",
        "path: selftest::ExceptionFromSuiteStartUp",
        "error<unexpected exception: std::bad_exception>: failed",
        "path: selftest::ExceptionFromSuiteStartUp",
        "leaveAssert<>",
        "path: selftest::ExceptionFromSuiteStartUp",
        "leaveSuite<ExceptionFromSuiteStartUp>: failed",
        "path: selftest::ExceptionFromSuiteStartUp",
        "leaveTest<selftest>: failed",
        "path: selftest",
      };

      testAssert(!runtime.runTheTest());
      testAssert(runtime.reporter.checkRecords(data_));
//      runtime.reporter.dumpRecords(std::cout);
    }
  }

  TEST_CASE(ExceptionFromSuiteTearDown) {
    Runtime runtime("ExceptionFromSuiteTearDown", "", Runtime::report_paths_mark);

    TEST_SIMPLE() {
      std::vector<const char*> data_{
        "enterTest<selftest>",
        "path: selftest",
        "enterSuite<ExceptionFromSuiteTearDown>",
        "path: selftest::ExceptionFromSuiteTearDown",
        "enterCase<DummyCase>",
        "path: selftest::ExceptionFromSuiteTearDown::DummyCase",
        "enterState<AnonymousState>",
        "path: selftest::ExceptionFromSuiteTearDown::DummyCase",
        "leaveState<AnonymousState>: passed",
        "path: selftest::ExceptionFromSuiteTearDown::DummyCase",
        "leaveCase<DummyCase>: passed",
        "path: selftest::ExceptionFromSuiteTearDown::DummyCase",
        "error<unexpected exception: std::bad_exception>: failed",
        "path: selftest::ExceptionFromSuiteTearDown",
        "leaveAssert<>",
        "path: selftest::ExceptionFromSuiteTearDown",
        "leaveSuite<ExceptionFromSuiteTearDown>: failed",
        "path: selftest::ExceptionFromSuiteTearDown",
        "leaveTest<selftest>: failed",
        "path: selftest",
      };

      testAssert(!runtime.runTheTest());
      testAssert(runtime.reporter.checkRecords(data_));
//      runtime.reporter.dumpRecords(std::cout);
    }
  }
}

} /* -- namespace Test */

} /* -- namespace OTest2 */
